Workbook
Name UPDATE: 'Data Sheet'!$E$1

Sheet Profit & Loss
A1: ='Data Sheet'!B1 -> HINDUSTAN UNILEVER LTD | H1: =UPDATE | M1: SCREENER.IN
A3: Narration | B3: ='Data Sheet'!B16 -> 42825 | C3: ='Data Sheet'!C16 -> 43190 | D3: ='Data Sheet'!D16 -> 43555 | E3: ='Data Sheet'!E16 -> 43921 | F3: ='Data Sheet'!F16 -> 44286 | G3: ='Data Sheet'!G16 -> 44651 | H3: ='Data Sheet'!H16 -> 45016 | I3: ='Data Sheet'!I16 -> 45382 | ... K3: ='Data Sheet'!K16 -> 46112 | L3: Trailing | M3: Best Case | N3: Worst Case
A4: Sales | B4: ='Data Sheet'!B17 -> 33162 | C4: ='Data Sheet'!C17 -> 35545 | D4: ='Data Sheet'!D17 -> 39310 | E4: ='Data Sheet'!E17 -> 39783 | F4: ='Data Sheet'!F17 -> 47028 | G4: ='Data Sheet'!G17 -> 52446 | H4: ='Data Sheet'!H17 -> 60580 | I4: ='Data Sheet'!I17 -> 61896 | ... K4: ='Data Sheet'!K17 -> 64468 | L4: =SUM(Quarters!H4:K4) -> 65225 | M4: =$K4+M23*K4 -> 67768.768 | N4: =$K4+N23*L4 -> 65834.541
A5: Expenses | B5: =SUM('Data Sheet'!B18,'Data Sheet'!B20:B24, -1*'Data Sheet'!B19) -> 26834 | C5: =SUM('Data Sheet'!C18,'Data Sheet'!C20:C24, -1*'Data Sheet'!C19) -> 28046 | D5: =SUM('Data Sheet'!D18,'Data Sheet'!D20:D24, -1*'Data Sheet'!D19) -> 30430 | E5: =SUM('Data Sheet'!E18,'Data Sheet'!E20:E24, -1*'Data Sheet'!E19) -> 29922 | F5: =SUM('Data Sheet'!F18,'Data Sheet'!F20:F24, -1*'Data Sheet'!F19) -> 35402 | G5: =SUM('Data Sheet'!G18,'Data Sheet'!G20:G24, -1*'Data Sheet'!G19) -> 39589 | H5: =SUM('Data Sheet'!H18,'Data Sheet'!H20:H24, -1*'Data Sheet'!H19) -> 46433 | I5: =SUM('Data Sheet'!I18,'Data Sheet'!I20:I24, -1*'Data Sheet'!I19) -> 47237 | ... K5: =SUM('Data Sheet'!K18,'Data Sheet'!K20:K24, -1*'Data Sheet'!K19) -> 49429 | L5: =SUM(Quarters!H5:K5) -> 50108 | M5: =M4-M6 -> 51738.984 | N5: =N4-N6 -> 50576.269
A6: Operating Profit | B6: =B4-B5 -> 6328 | C6: =C4-C5 -> 7499 | D6: =D4-D5 -> 8880 | E6: =E4-E5 -> 9861 | F6: =F4-F5 -> 11626 | G6: =G4-G5 -> 12857 | H6: =H4-H5 -> 14147 | I6: =I4-I5 -> 14659 | ... K6: =K4-K5 -> 15039 | L6: =SUM(Quarters!H6:K6) -> 15117 | M6: =M4*M24 -> 16029.784 | N6: =N4*N24 -> 15258.271
A7: Other Income | B7: ='Data Sheet'!B25 -> 606 | C7: ='Data Sheet'!C25 -> 353 | D7: ='Data Sheet'!D25 -> 322 | E7: ='Data Sheet'!E25 -> 424 | F7: ='Data Sheet'!F25 -> 170 | G7: ='Data Sheet'!G25 -> 219 | H7: ='Data Sheet'!H25 -> 448 | I7: ='Data Sheet'!I25 -> 817 | ... K7: ='Data Sheet'!K25 -> 4923 | L7: =SUM(Quarters!H7:K7) -> 4894 | M7: 0 | N7: 0
A8: Depreciation | B8: ='Data Sheet'!B26 -> 432 | C8: ='Data Sheet'!C26 -> 520 | D8: ='Data Sheet'!D26 -> 565 | E8: ='Data Sheet'!E26 -> 1002 | F8: ='Data Sheet'!F26 -> 1074 | G8: ='Data Sheet'!G26 -> 1091 | H8: ='Data Sheet'!H26 -> 1137 | I8: ='Data Sheet'!I26 -> 1216 | ... K8: ='Data Sheet'!K26 -> 1333 | L8: =SUM(Quarters!H8:K8) -> 1368 | M8: =+$L8 -> 1368 | N8: =+$L8 -> 1368
A9: Interest | B9: ='Data Sheet'!B27 -> 35 | C9: ='Data Sheet'!C27 -> 26 | D9: ='Data Sheet'!D27 -> 33 | E9: ='Data Sheet'!E27 -> 118 | F9: ='Data Sheet'!F27 -> 117 | G9: ='Data Sheet'!G27 -> 106 | H9: ='Data Sheet'!H27 -> 114 | I9: ='Data Sheet'!I27 -> 334 | ... K9: ='Data Sheet'!K27 -> 410 | L9: =SUM(Quarters!H9:K9) -> 415 | M9: =+$L9 -> 415 | N9: =+$L9 -> 415
A10: Profit before tax | B10: ='Data Sheet'!B28 -> 6467 | C10: ='Data Sheet'!C28 -> 7306 | D10: ='Data Sheet'!D28 -> 8604 | E10: ='Data Sheet'!E28 -> 9165 | F10: ='Data Sheet'!F28 -> 10605 | G10: ='Data Sheet'!G28 -> 11879 | H10: ='Data Sheet'!H28 -> 13344 | I10: ='Data Sheet'!I28 -> 13926 | ... K10: ='Data Sheet'!K28 -> 18219 | L10: =SUM(Quarters!H10:K10) -> 18228 | M10: =M6+M7-SUM(M8:M9) -> 14246.784 | N10: =N6+N7-SUM(N8:N9) -> 13475.271
A11: Tax | B11: ='Data Sheet'!B29 -> 1977 | C11: ='Data Sheet'!C29 -> 2079 | D11: ='Data Sheet'!D29 -> 2544 | E11: ='Data Sheet'!E29 -> 2409 | F11: ='Data Sheet'!F29 -> 2606 | G11: ='Data Sheet'!G29 -> 2987 | H11: ='Data Sheet'!H29 -> 3201 | I11: ='Data Sheet'!I29 -> 3644 | ... K11: ='Data Sheet'!K29 -> 3160 | L11: =SUM(Quarters!H11:K11) -> 3169 | M11: =IF($L10>0,$L11/$L10,0) -> 0.17385341 | N11: =IF($L10>0,$L11/$L10,0) -> 0.17385341
A12: Net profit | B12: ='Data Sheet'!B30 -> 4476 | C12: ='Data Sheet'!C30 -> 5214 | D12: ='Data Sheet'!D30 -> 6054 | E12: ='Data Sheet'!E30 -> 6748 | F12: ='Data Sheet'!F30 -> 7995 | G12: ='Data Sheet'!G30 -> 8879 | H12: ='Data Sheet'!H30 -> 10120 | I12: ='Data Sheet'!I30 -> 10277 | ... K12: ='Data Sheet'!K30 -> 15040 | L12: =SUM(Quarters!H12:K12) -> 15040 | M12: =M10-M11*M10 -> 11769.932 | N12: =N10-N11*N10 -> 11132.55
A13: EPS | B13: =IF('Data Sheet'!B94>0,B12/'Data Sheet'!B94,0) -> 20.681052 | C13: =IF('Data Sheet'!C94>0,C12/'Data Sheet'!C94,0) -> 24.088704 | D13: =IF('Data Sheet'!D94>0,D12/'Data Sheet'!D94,0) -> 27.966924 | E13: =IF('Data Sheet'!E94>0,E12/'Data Sheet'!E94,0) -> 31.171471 | F13: =IF('Data Sheet'!F94>0,F12/'Data Sheet'!F94,0) -> 34.027068 | G13: =IF('Data Sheet'!G94>0,G12/'Data Sheet'!G94,0) -> 37.789411 | H13: =IF('Data Sheet'!H94>0,H12/'Data Sheet'!H94,0) -> 43.071161 | I13: =IF('Data Sheet'!I94>0,I12/'Data Sheet'!I94,0) -> 43.73936 | ... K13: =IF('Data Sheet'!K94>0,K12/'Data Sheet'!K94,0) -> 64.010895 | L13: =IF('Data Sheet'!$B6>0,'Profit & Loss'!L12/'Data Sheet'!$B6,0) -> 64.011135 | M13: =IF('Data Sheet'!$B6>0,'Profit & Loss'!M12/'Data Sheet'!$B6,0) -> 50.093531 | N13: =IF('Data Sheet'!$B6>0,'Profit & Loss'!N12/'Data Sheet'!$B6,0) -> 47.380793
A14: Price to earning | B14: =IF(B15>0,B15/B13,"") -> 42.193696 | C14: =IF(C15>0,C15/C13,"") -> 52.975453 | D14: =IF(D15>0,D15/D13,"") -> 58.409356 | E14: =IF(E15>0,E15/E13,"") -> 70.571903 | F14: =IF(F15>0,F15/F13,"") -> 68.390258 | G14: =IF(G15>0,G15/G13,"") -> 51.884905 | H14: =IF(H15>0,H15/H13,"") -> 56.892824 | I14: =IF(I15>0,I15/I13,"") -> 49.546678 | ... K14: =IF(K15>0,K15/K13,"") -> 32.107034 | L14: =IF(L13>0,L15/L13,0) -> 34.509621 | M14: =M25 -> 40.965787 | N14: =N25 -> 34.509621
A15: Price | B15: ='Data Sheet'!B91 -> 872.61 | C15: ='Data Sheet'!C91 -> 1276.11 | D15: ='Data Sheet'!D91 -> 1633.53 | E15: ='Data Sheet'!E91 -> 2199.83 | F15: ='Data Sheet'!F91 -> 2327.12 | G15: ='Data Sheet'!G91 -> 1960.7 | H15: ='Data Sheet'!H91 -> 2450.44 | I15: ='Data Sheet'!I91 -> 2167.14 | ... K15: ='Data Sheet'!K91 -> 2055.2 | L15: ='Data Sheet'!B8 -> 2209 | M15: =M13*M14 -> 2052.1209 | N15: =N13*N14 -> 1635.0932
A17: RATIOS:
A18: Dividend Payout | B18: =IF('Data Sheet'!B30>0, 'Data Sheet'!B31/'Data Sheet'!B30, 0) -> 0.82037534 | C18: =IF('Data Sheet'!C30>0, 'Data Sheet'!C31/'Data Sheet'!C30, 0) -> 0.82853855 | D18: =IF('Data Sheet'!D30>0, 'Data Sheet'!D31/'Data Sheet'!D30, 0) -> 0.78493558 | E18: =IF('Data Sheet'!E30>0, 'Data Sheet'!E31/'Data Sheet'!E30, 0) -> 0.80023711 | F18: =IF('Data Sheet'!F30>0, 'Data Sheet'!F31/'Data Sheet'!F30, 0) -> 1.1904315 | G18: =IF('Data Sheet'!G30>0, 'Data Sheet'!G31/'Data Sheet'!G30, 0) -> 0.89987611 | H18: =IF('Data Sheet'!H30>0, 'Data Sheet'!H31/'Data Sheet'!H30, 0) -> 0.90563241 | I18: =IF('Data Sheet'!I30>0, 'Data Sheet'!I31/'Data Sheet'!I30, 0) -> 0.960397 | ... K18: =IF('Data Sheet'!K30>0, 'Data Sheet'!K31/'Data Sheet'!K30, 0) -> 0.640625
A19: OPM | B19: =IF(B6>0,B6/B4,0) -> 0.19082082 | C19: =IF(C6>0,C6/C4,0) -> 0.21097201 | D19: =IF(D6>0,D6/D4,0) -> 0.22589672 | E19: =IF(E6>0,E6/E4,0) -> 0.24786969 | F19: =IF(F6>0,F6/F4,0) -> 0.24721443 | G19: =IF(G6>0,G6/G4,0) -> 0.24514739 | H19: =IF(H6>0,H6/H4,0) -> 0.23352592 | I19: =IF(I6>0,I6/I4,0) -> 0.23683275 | ... L19: =IF(L6>0,L6/L4,0) -> 0.23176696
G22: TRENDS: | H22: 10 YEARS | I22: 7 YEARS | J22: 5 YEARS | K22: 3 YEARS | L22: RECENT | M22: BEST | N22: WORST
G23: Sales Growth | H23: =IF(B4=0,"",POWER($K4/B4,1/9)-1) -> 0.076658974 | I23: =IF(D4=0,"",POWER($K4/D4,1/7)-1) -> 0.073227008 | J23: =IF(F4=0,"",POWER($K4/F4,1/5)-1) -> 0.065117542 | K23: =IF(H4=0,"",POWER($K4/H4, 1/3)-1) -> 0.020951182 | L23: =IF(ISERROR(MAX(IF(J4=0,"",(K4-J4)/J4),IF(K4=0,"",(L4-K4)/K4))),"",MAX(IF(J4=0,"",(K4-J4)/J4),IF(K4=0,"",(L4-K4)/K4))) -> 0.051200104 | M23: =MAX(K23:L23) -> 0.051200104 | N23: =MIN(H23:L23) -> 0.020951182
G24: OPM | H24: =IF(SUM(B4:$K$4)=0,"",SUMPRODUCT(B19:$K$19,B4:$K$4)/SUM(B4:$K$4)) -> 0.23326593 | I24: =IF(SUM(E4:$K$4)=0,"",SUMPRODUCT(E19:$K$19,E4:$K$4)/SUM(E4:$K$4)) -> 0.23969045 | J24: =IF(SUM(G4:$K$4)=0,"",SUMPRODUCT(G19:$K$19,G4:$K$4)/SUM(G4:$K$4)) -> 0.23743175 | K24: =IF(SUM(I4:$K$4)=0, "", SUMPRODUCT(I19:$K$19,I4:$K$4)/SUM(I4:$K$4)) -> 0.23653645 | L24: =L19 -> 0.23176696 | M24: =MAX(K24:L24) -> 0.23653645 | N24: =MIN(H24:L24) -> 0.23176696
G25: Price to Earning | H25: =IF(ISERROR(AVERAGEIF(B14:$L14,">0")),"",AVERAGEIF(B14:$L14,">0")) -> 51.38014 | I25: =IF(ISERROR(AVERAGEIF(E14:$L14,">0")),"",AVERAGEIF(E14:$L14,">0")) -> 51.45038 | J25: =IF(ISERROR(AVERAGEIF(G14:$L14,">0")),"",AVERAGEIF(G14:$L14,">0")) -> 45.440146 | K25: =IF(ISERROR(AVERAGEIF(I14:$L14,">0")),"",AVERAGEIF(I14:$L14,">0")) -> 40.965787 | L25: =L14 -> 34.509621 | M25: =MAX(K25:L25) -> 40.965787 | N25: =MIN(H25:L25) -> 34.509621

Sheet Quarters
A1: ='Profit & Loss'!A1 -> HINDUSTAN UNILEVER LTD | E1: =UPDATE | J1: SCREENER.IN
A3: Narration | B3: ='Data Sheet'!B41 -> 45291 | C3: ='Data Sheet'!C41 -> 45382 | D3: ='Data Sheet'!D41 -> 45473 | E3: ='Data Sheet'!E41 -> 45565 | F3: ='Data Sheet'!F41 -> 45657 | G3: ='Data Sheet'!G41 -> 45747 | H3: ='Data Sheet'!H41 -> 45838 | I3: ='Data Sheet'!I41 -> 45930 | ... K3: ='Data Sheet'!K41 -> 46112
A4: Sales | B4: ='Data Sheet'!B42 -> 15567 | C4: ='Data Sheet'!C42 -> 15210 | D4: ='Data Sheet'!D42 -> 15707 | E4: ='Data Sheet'!E42 -> 15926 | F4: ='Data Sheet'!F42 -> 15556 | G4: ='Data Sheet'!G42 -> 15190 | H4: ='Data Sheet'!H42 -> 16514 | I4: ='Data Sheet'!I42 -> 15919 | ... K4: ='Data Sheet'!K42 -> 16351
A5: Expenses | B5: ='Data Sheet'!B43 -> 11902 | C5: ='Data Sheet'!C43 -> 11675 | D5: ='Data Sheet'!D43 -> 11965 | E5: ='Data Sheet'!E43 -> 12139 | F5: ='Data Sheet'!F43 -> 11867 | G5: ='Data Sheet'!G43 -> 11572 | H5: ='Data Sheet'!H43 -> 12797 | I5: ='Data Sheet'!I43 -> 12137 | ... K5: ='Data Sheet'!K43 -> 12514
A6: Operating Profit | B6: ='Data Sheet'!B50 -> 3665 | C6: ='Data Sheet'!C50 -> 3535 | D6: ='Data Sheet'!D50 -> 3742 | E6: ='Data Sheet'!E50 -> 3787 | F6: ='Data Sheet'!F50 -> 3689 | G6: ='Data Sheet'!G50 -> 3618 | H6: ='Data Sheet'!H50 -> 3717 | I6: ='Data Sheet'!I50 -> 3782 | ... K6: ='Data Sheet'!K50 -> 3837
A7: Other Income | B7: ='Data Sheet'!B44 -> 184 | C7: ='Data Sheet'!C44 -> 309 | D7: ='Data Sheet'!D44 -> 209 | E7: ='Data Sheet'!E44 -> 203 | F7: ='Data Sheet'!F44 -> 733 | G7: ='Data Sheet'!G44 -> 149 | H7: ='Data Sheet'!H44 -> 74 | I7: ='Data Sheet'!I44 -> 269 | ... K7: ='Data Sheet'!K44 -> 503
A8: Depreciation | B8: ='Data Sheet'!B45 -> 313 | C8: ='Data Sheet'!C45 -> 320 | D8: ='Data Sheet'!D45 -> 329 | E8: ='Data Sheet'!E45 -> 338 | F8: ='Data Sheet'!F45 -> 318 | G8: ='Data Sheet'!G45 -> 318 | H8: ='Data Sheet'!H45 -> 361 | I8: ='Data Sheet'!I45 -> 322 | ... K8: ='Data Sheet'!K45 -> 348
A9: Interest | B9: ='Data Sheet'!B46 -> 91 | C9: ='Data Sheet'!C46 -> 105 | D9: ='Data Sheet'!D46 -> 93 | E9: ='Data Sheet'!E46 -> 110 | F9: ='Data Sheet'!F46 -> 109 | G9: ='Data Sheet'!G46 -> 77 | H9: ='Data Sheet'!H46 -> 127 | I9: ='Data Sheet'!I46 -> 124 | ... K9: ='Data Sheet'!K46 -> 76
A10: Profit before tax | B10: ='Data Sheet'!B47 -> 3445 | C10: ='Data Sheet'!C47 -> 3419 | D10: ='Data Sheet'!D47 -> 3529 | E10: ='Data Sheet'!E47 -> 3542 | F10: ='Data Sheet'!F47 -> 3995 | G10: ='Data Sheet'!G47 -> 3372 | H10: ='Data Sheet'!H47 -> 3303 | I10: ='Data Sheet'!I47 -> 3605 | ... K10: ='Data Sheet'!K47 -> 3916
A11: Tax | B11: ='Data Sheet'!B48 -> 937 | C11: ='Data Sheet'!C48 -> 858 | D11: ='Data Sheet'!D48 -> 917 | E11: ='Data Sheet'!E48 -> 947 | F11: ='Data Sheet'!F48 -> 1006 | G11: ='Data Sheet'!G48 -> 897 | H11: ='Data Sheet'!H48 -> 535 | I11: ='Data Sheet'!I48 -> 911 | ... K11: ='Data Sheet'!K48 -> 922
A12: Net profit | B12: ='Data Sheet'!B49 -> 2509 | C12: ='Data Sheet'!C49 -> 2558 | D12: ='Data Sheet'!D49 -> 2610 | E12: ='Data Sheet'!E49 -> 2591 | F12: ='Data Sheet'!F49 -> 2984 | G12: ='Data Sheet'!G49 -> 2464 | H12: ='Data Sheet'!H49 -> 2756 | I12: ='Data Sheet'!I49 -> 2685 | ... K12: ='Data Sheet'!K49 -> 2992
A14: OPM | B14: =IF(B4>0,B6/B4,"") -> 0.23543393 | C14: =IF(C4>0,C6/C4,"") -> 0.23241289 | D14: =IF(D4>0,D6/D4,"") -> 0.23823773 | E14: =IF(E4>0,E6/E4,"") -> 0.23778727 | F14: =IF(F4>0,F6/F4,"") -> 0.23714322 | G14: =IF(G4>0,G6/G4,"") -> 0.23818302 | H14: =IF(H4>0,H6/H4,"") -> 0.22508175 | I14: =IF(I4>0,I6/I4,"") -> 0.23757774 | ... K14: =IF(K4>0,K6/K4,"") -> 0.23466455

Sheet Balance Sheet
A1: ='Profit & Loss'!A1 -> HINDUSTAN UNILEVER LTD | E1: =UPDATE | J1: SCREENER.IN
A3: Narration | B3: ='Data Sheet'!B56 -> 42825 | C3: ='Data Sheet'!C56 -> 43190 | D3: ='Data Sheet'!D56 -> 43555 | E3: ='Data Sheet'!E56 -> 43921 | F3: ='Data Sheet'!F56 -> 44286 | G3: ='Data Sheet'!G56 -> 44651 | H3: ='Data Sheet'!H56 -> 45016 | I3: ='Data Sheet'!I56 -> 45382 | ... K3: ='Data Sheet'!K56 -> 46112
A4: Equity Share Capital | B4: ='Data Sheet'!B57 -> 216 | C4: ='Data Sheet'!C57 -> 216 | D4: ='Data Sheet'!D57 -> 216 | E4: ='Data Sheet'!E57 -> 216 | F4: ='Data Sheet'!F57 -> 235 | G4: ='Data Sheet'!G57 -> 235 | H4: ='Data Sheet'!H57 -> 235 | I4: ='Data Sheet'!I57 -> 235 | ... K4: ='Data Sheet'!K57 -> 235
A5: Reserves | B5: ='Data Sheet'!B58 -> 6528 | C5: ='Data Sheet'!C58 -> 7065 | D5: ='Data Sheet'!D58 -> 7651 | E5: ='Data Sheet'!E58 -> 8013 | F5: ='Data Sheet'!F58 -> 47439 | G5: ='Data Sheet'!G58 -> 48826 | H5: ='Data Sheet'!H58 -> 50069 | I5: ='Data Sheet'!I58 -> 50983 | ... K5: ='Data Sheet'!K58 -> 48504
A6: Borrowings | B6: ='Data Sheet'!B59 -> 277 | C6: ='Data Sheet'!C59 -> 0 | D6: ='Data Sheet'!D59 -> 99 | E6: ='Data Sheet'!E59 -> 0 | F6: ='Data Sheet'!F59 -> 0 | G6: ='Data Sheet'!G59 -> 1043 | H6: ='Data Sheet'!H59 -> 1219 | I6: ='Data Sheet'!I59 -> 1484 | ... K6: ='Data Sheet'!K59 -> 1478
A7: Other Liabilities | B7: ='Data Sheet'!B60 -> 2499 | C7: ='Data Sheet'!C60 -> 3411 | D7: ='Data Sheet'!D60 -> 3457 | E7: ='Data Sheet'!E60 -> 4389 | F7: ='Data Sheet'!F60 -> 12264 | G7: ='Data Sheet'!G60 -> 11334 | H7: ='Data Sheet'!H60 -> 11980 | I7: ='Data Sheet'!I60 -> 15301 | ... K7: ='Data Sheet'!K60 -> 16196
A8: Total | B8: ='Data Sheet'!B62 -> 15706 | C8: ='Data Sheet'!C62 -> 17862 | D8: ='Data Sheet'!D62 -> 18629 | E8: ='Data Sheet'!E62 -> 20153 | F8: ='Data Sheet'!F62 -> 68740 | G8: ='Data Sheet'!G62 -> 70506 | H8: ='Data Sheet'!H62 -> 73077 | I8: ='Data Sheet'!I62 -> 78489 | ... K8: ='Data Sheet'!K62 -> 79738
A10: Net Block | B10: ='Data Sheet'!B63 -> 4419 | C10: ='Data Sheet'!C63 -> 4528 | D10: ='Data Sheet'!D63 -> 4715 | E10: ='Data Sheet'!E63 -> 5479 | F10: ='Data Sheet'!F63 -> 51443 | G10: ='Data Sheet'!G63 -> 51473 | H10: ='Data Sheet'!H63 -> 52678 | I10: ='Data Sheet'!I63 -> 53744 | ... K10: ='Data Sheet'!K63 -> 57428
A11: Capital Work in Progress | B11: ='Data Sheet'!B64 -> 229 | C11: ='Data Sheet'!C64 -> 461 | D11: ='Data Sheet'!D64 -> 406 | E11: ='Data Sheet'!E64 -> 597 | F11: ='Data Sheet'!F64 -> 745 | G11: ='Data Sheet'!G64 -> 1313 | H11: ='Data Sheet'!H64 -> 1132 | I11: ='Data Sheet'!I64 -> 1025 | ... K11: ='Data Sheet'!K64 -> 880
A12: Investments | B12: ='Data Sheet'!B65 -> 3794 | C12: ='Data Sheet'!C65 -> 2873 | D12: ='Data Sheet'!D65 -> 2716 | E12: ='Data Sheet'!E65 -> 1255 | F12: ='Data Sheet'!F65 -> 2709 | G12: ='Data Sheet'!G65 -> 3521 | H12: ='Data Sheet'!H65 -> 2882 | I12: ='Data Sheet'!I65 -> 4625 | ... K12: ='Data Sheet'!K65 -> 4359
A13: Other Assets | B13: ='Data Sheet'!B66 -> 7264 | C13: ='Data Sheet'!C66 -> 10000 | D13: ='Data Sheet'!D66 -> 10792 | E13: ='Data Sheet'!E66 -> 12822 | F13: ='Data Sheet'!F66 -> 13843 | G13: ='Data Sheet'!G66 -> 14199 | H13: ='Data Sheet'!H66 -> 16385 | I13: ='Data Sheet'!I66 -> 19095 | ... K13: ='Data Sheet'!K66 -> 17071
A14: Total | B14: ='Data Sheet'!B67 -> 15706 | C14: ='Data Sheet'!C67 -> 17862 | D14: ='Data Sheet'!D67 -> 18629 | E14: ='Data Sheet'!E67 -> 20153 | F14: ='Data Sheet'!F67 -> 68740 | G14: ='Data Sheet'!G67 -> 70506 | H14: ='Data Sheet'!H67 -> 73077 | I14: ='Data Sheet'!I67 -> 78489 | ... K14: ='Data Sheet'!K67 -> 79738
A16: Working Capital | B16: =B13-B7 -> 4765 | C16: =C13-C7 -> 6589 | D16: =D13-D7 -> 7335 | E16: =E13-E7 -> 8433 | F16: =F13-F7 -> 1579 | G16: =G13-G7 -> 2865 | H16: =H13-H7 -> 4405 | I16: =I13-I7 -> 3794 | ... K16: =K13-K7 -> 875
A17: Debtors | B17: ='Data Sheet'!B68 -> 1085 | C17: ='Data Sheet'!C68 -> 1310 | D17: ='Data Sheet'!D68 -> 1816 | E17: ='Data Sheet'!E68 -> 1149 | F17: ='Data Sheet'!F68 -> 1758 | G17: ='Data Sheet'!G68 -> 2236 | H17: ='Data Sheet'!H68 -> 3079 | I17: ='Data Sheet'!I68 -> 2997 | ... K17: ='Data Sheet'!K68 -> 3379
A18: Inventory | B18: ='Data Sheet'!B69 -> 2541 | C18: ='Data Sheet'!C69 -> 2513 | D18: ='Data Sheet'!D69 -> 2574 | E18: ='Data Sheet'!E69 -> 2767 | F18: ='Data Sheet'!F69 -> 3579 | G18: ='Data Sheet'!G69 -> 4096 | H18: ='Data Sheet'!H69 -> 4251 | I18: ='Data Sheet'!I69 -> 4022 | ... K18: ='Data Sheet'!K69 -> 4789
A20: Debtor Days | B20: =IF('Profit & Loss'!B4>0,'Balance Sheet'!B17/('Profit & Loss'!B4/365),0) -> 11.942133 | C20: =IF('Profit & Loss'!C4>0,'Balance Sheet'!C17/('Profit & Loss'!C4/365),0) -> 13.451962 | D20: =IF('Profit & Loss'!D4>0,'Balance Sheet'!D17/('Profit & Loss'!D4/365),0) -> 16.861867 | E20: =IF('Profit & Loss'!E4>0,'Balance Sheet'!E17/('Profit & Loss'!E4/365),0) -> 10.541814 | F20: =IF('Profit & Loss'!F4>0,'Balance Sheet'!F17/('Profit & Loss'!F4/365),0) -> 13.644425 | G20: =IF('Profit & Loss'!G4>0,'Balance Sheet'!G17/('Profit & Loss'!G4/365),0) -> 15.56153 | H20: =IF('Profit & Loss'!H4>0,'Balance Sheet'!H17/('Profit & Loss'!H4/365),0) -> 18.551255 | I20: =IF('Profit & Loss'!I4>0,'Balance Sheet'!I17/('Profit & Loss'!I4/365),0) -> 17.673275 | ... K20: =IF('Profit & Loss'!K4>0,'Balance Sheet'!K17/('Profit & Loss'!K4/365),0) -> 19.130964
A21: Inventory Turnover | B21: =IF('Balance Sheet'!B18>0,'Profit & Loss'!B4/'Balance Sheet'!B18,0) -> 13.050767 | C21: =IF('Balance Sheet'!C18>0,'Profit & Loss'!C4/'Balance Sheet'!C18,0) -> 14.144449 | D21: =IF('Balance Sheet'!D18>0,'Profit & Loss'!D4/'Balance Sheet'!D18,0) -> 15.27195 | E21: =IF('Balance Sheet'!E18>0,'Profit & Loss'!E4/'Balance Sheet'!E18,0) -> 14.377665 | F21: =IF('Balance Sheet'!F18>0,'Profit & Loss'!F4/'Balance Sheet'!F18,0) -> 13.139983 | G21: =IF('Balance Sheet'!G18>0,'Profit & Loss'!G4/'Balance Sheet'!G18,0) -> 12.804199 | H21: =IF('Balance Sheet'!H18>0,'Profit & Loss'!H4/'Balance Sheet'!H18,0) -> 14.250765 | I21: =IF('Balance Sheet'!I18>0,'Profit & Loss'!I4/'Balance Sheet'!I18,0) -> 15.389359 | ... K21: =IF('Balance Sheet'!K18>0,'Profit & Loss'!K4/'Balance Sheet'!K18,0) -> 13.461683
A23: Return on Equity | B23: =IF(SUM('Balance Sheet'!B4:B5)>0,'Profit & Loss'!B12/SUM('Balance Sheet'!B4:B5),"") -> 0.66370107 | C23: =IF(SUM('Balance Sheet'!C4:C5)>0,'Profit & Loss'!C12/SUM('Balance Sheet'!C4:C5),"") -> 0.71611042 | D23: =IF(SUM('Balance Sheet'!D4:D5)>0,'Profit & Loss'!D12/SUM('Balance Sheet'!D4:D5),"") -> 0.76954366 | E23: =IF(SUM('Balance Sheet'!E4:E5)>0,'Profit & Loss'!E12/SUM('Balance Sheet'!E4:E5),"") -> 0.82002673 | F23: =IF(SUM('Balance Sheet'!F4:F5)>0,'Profit & Loss'!F12/SUM('Balance Sheet'!F4:F5),"") -> 0.16770147 | G23: =IF(SUM('Balance Sheet'!G4:G5)>0,'Profit & Loss'!G12/SUM('Balance Sheet'!G4:G5),"") -> 0.18097878 | H23: =IF(SUM('Balance Sheet'!H4:H5)>0,'Profit & Loss'!H12/SUM('Balance Sheet'!H4:H5),"") -> 0.20117684 | I23: =IF(SUM('Balance Sheet'!I4:I5)>0,'Profit & Loss'!I12/SUM('Balance Sheet'!I4:I5),"") -> 0.20065211 | ... K23: =IF(SUM('Balance Sheet'!K4:K5)>0,'Profit & Loss'!K12/SUM('Balance Sheet'!K4:K5),"") -> 0.30858245
A24: Return on Capital Emp | C24: =IF((B4+B5+B6+C4+C5+C6)>0,('Profit & Loss'!C10+'Profit & Loss'!C9)*2/(B4+B5+B6+C4+C5+C6),"") -> 1.0253111 | D24: =IF((C4+C5+C6+D4+D5+D6)>0,('Profit & Loss'!D10+'Profit & Loss'!D9)*2/(C4+C5+C6+D4+D5+D6),"") -> 1.1329442 | E24: =IF((D4+D5+D6+E4+E5+E6)>0,('Profit & Loss'!E10+'Profit & Loss'!E9)*2/(D4+D5+D6+E4+E5+E6),"") -> 1.1464032 | F24: =IF((E4+E5+E6+F4+F5+F6)>0,('Profit & Loss'!F10+'Profit & Loss'!F9)*2/(E4+E5+E6+F4+F5+F6),"") -> 0.38359301 | G24: =IF((F4+F5+F6+G4+G5+G6)>0,('Profit & Loss'!G10+'Profit & Loss'!G9)*2/(F4+F5+F6+G4+G5+G6),"") -> 0.24514717 | H24: =IF((G4+G5+G6+H4+H5+H6)>0,('Profit & Loss'!H10+'Profit & Loss'!H9)*2/(G4+G5+G6+H4+H5+H6),"") -> 0.26485088 | I24: =IF((H4+H5+H6+I4+I5+I6)>0,('Profit & Loss'!I10+'Profit & Loss'!I9)*2/(H4+H5+H6+I4+I5+I6),"") -> 0.27363876 | J24: =IF((I4+I5+I6+J4+J5+J6)>0,('Profit & Loss'!J10+'Profit & Loss'!J9)*2/(I4+I5+I6+J4+J5+J6),"") -> 0.28529571 | K24: =IF((J4+J5+J6+K4+K5+K6)>0,('Profit & Loss'!K10+'Profit & Loss'!K9)*2/(J4+J5+J6+K4+K5+K6),"") -> 0.36791847

Sheet Cash Flow
A1: ='Balance Sheet'!A1 -> HINDUSTAN UNILEVER LTD | E1: =UPDATE | J1: SCREENER.IN
A3: Narration | B3: ='Data Sheet'!B82 -> 42825 | C3: ='Data Sheet'!C82 -> 43190 | D3: ='Data Sheet'!D82 -> 43555 | E3: ='Data Sheet'!E82 -> 43921 | F3: ='Data Sheet'!F82 -> 44286 | G3: ='Data Sheet'!G82 -> 44651 | H3: ='Data Sheet'!H82 -> 45016 | I3: ='Data Sheet'!I82 -> 45382 | ... K3: ='Data Sheet'!K82 -> 46112
A4: Cash from Operating Activity | B4: ='Data Sheet'!B83 -> 5185 | C4: ='Data Sheet'!C83 -> 6059 | D4: ='Data Sheet'!D83 -> 5800 | E4: ='Data Sheet'!E83 -> 7623 | F4: ='Data Sheet'!F83 -> 9163 | G4: ='Data Sheet'!G83 -> 9048 | H4: ='Data Sheet'!H83 -> 9991 | I4: ='Data Sheet'!I83 -> 15469 | ... K4: ='Data Sheet'!K83 -> 10999
A5: Cash from Investing Activity | B5: ='Data Sheet'!B84 -> -1173 | C5: ='Data Sheet'!C84 -> -1063 | D5: ='Data Sheet'!D84 -> -438 | E5: ='Data Sheet'!E84 -> 1791 | F5: ='Data Sheet'!F84 -> -1228 | G5: ='Data Sheet'!G84 -> -1728 | H5: ='Data Sheet'!H84 -> -1484 | I5: ='Data Sheet'!I84 -> -5324 | ... K5: ='Data Sheet'!K84 -> -3676
A6: Cash from Financing Activity | B6: ='Data Sheet'!B85 -> -4214 | C6: ='Data Sheet'!C85 -> -4975 | D6: ='Data Sheet'!D85 -> -5390 | E6: ='Data Sheet'!E85 -> -6819 | F6: ='Data Sheet'!F85 -> -9309 | G6: ='Data Sheet'!G85 -> -8015 | H6: ='Data Sheet'!H85 -> -8953 | I6: ='Data Sheet'!I85 -> -10034 | ... K6: ='Data Sheet'!K85 -> -10810
A7: Net Cash Flow | B7: ='Data Sheet'!B86 -> -202 | C7: ='Data Sheet'!C86 -> 21 | D7: ='Data Sheet'!D86 -> -28 | E7: ='Data Sheet'!E86 -> 2595 | F7: ='Data Sheet'!F86 -> -1374 | G7: ='Data Sheet'!G86 -> -695 | H7: ='Data Sheet'!H86 -> -446 | I7: ='Data Sheet'!I86 -> 111 | ... K7: ='Data Sheet'!K86 -> -3487

Sheet Customization
A1: How to use it?
A3: You can customize this workbook as you want.
B4: You can add custom formating, add conditional formating, add your own formulas… do ANYTHING.
B5: Please don't edit the "Data Sheet" only.
A7: After customization, you can upload this back on Screener.
B8: Upload on: | C8: https://www.screener.in/excel/
A10: Download your customized workbooks now onwards.
B11: Now whenever you will "Export to excel" from Screener, it will export your customized file.
A14: TESTING:
B15: This is a testing feature currently.
B16: You can report any formula errors on the worksheet at: support@screener.in

Sheet Data Sheet
A1: COMPANY NAME | B1: HINDUSTAN UNILEVER LTD | E1: =IF(B2<>B3, "A NEW VERSION OF THE WORKSHEET IS AVAILABLE", "")
A2: LATEST VERSION | B2: 2.1 | E2: PLEASE DO NOT MAKE ANY CHANGES TO THIS SHEET
A3: CURRENT VERSION | B3: 2.1
A5: META
A6: Number of shares | B6: =IF(B9>0, B9/B8, 0) -> 234.95912
A7: Face Value | B7: 1
A8: Current Price | B8: 2209
A9: Market Capitalization | B9: 519024.7
A15: PROFIT & LOSS
A16: Report Date | B16: 42825 | C16: 43190 | D16: 43555 | E16: 43921 | F16: 44286 | G16: 44651 | H16: 45016 | I16: 45382 | J16: 45747 | K16: 46112
A17: Sales | B17: 33162 | C17: 35545 | D17: 39310 | E17: 39783 | F17: 47028 | G17: 52446 | H17: 60580 | I17: 61896 | J17: 61328 | K17: 64468
A18: Raw Material Cost | B18: 13606 | C18: 14233 | D18: 15845 | E18: 15697 | F18: 20141 | G18: 22871 | H18: 28427 | I18: 26822 | J18: 26602 | K18: 29158
A19: Change in Inventory | B19: -144 | C19: 72 | D19: -12 | E19: 108 | F19: 405 | G19: 22 | H19: 75 | I19: 11 | J19: 125 | K19: 429
A20: Power and Fuel | B20: 295 | C20: 295 | D20: 308 | E20: 299 | F20: 339 | G20: 318 | H20: 384 | I20: 446 | J20: 403 | K20: 426
A21: Other Mfr. Exp | B21: 2887 | C21: 2998 | D21: 3041 | E21: 2906 | F21: 2868 | G21: 3354 | H21: 3791 | I21: 3385 | J21: 3687 | K21: 3304
A22: Employee Cost | B22: 1743 | C22: 1860 | D22: 1875 | E22: 1820 | F22: 2358 | G22: 2545 | H22: 2854 | I22: 3009 | J22: 2952 | K22: 3175
A23: Selling and admin | B23: 6689 | C23: 7252 | D23: 7796 | E23: 7620 | F23: 7906 | G23: 8164 | H23: 8785 | I23: 10780 | J23: 10145 | K23: 10744
A24: Other Expenses | B24: 1470 | C24: 1480 | D24: 1553 | E24: 1688 | F24: 2195 | G24: 2359 | H24: 2267 | I24: 2806 | J24: 2966 | K24: 3051
A25: Other Income | B25: 606 | C25: 353 | D25: 322 | E25: 424 | F25: 170 | G25: 219 | H25: 448 | I25: 817 | J25: 1355 | K25: 4923
A26: Depreciation | B26: 432 | C26: 520 | D26: 565 | E26: 1002 | F26: 1074 | G26: 1091 | H26: 1137 | I26: 1216 | J26: 1253 | K26: 1333
A27: Interest | B27: 35 | C27: 26 | D27: 33 | E27: 118 | F27: 117 | G27: 106 | H27: 114 | I27: 334 | J27: 381 | K27: 410
... A31: Dividend Amount | B31: 3672 | C31: 4320 | D31: 4752 | E31: 5400 | F31: 9517.5 | G31: 7990 | H31: 9165 | I31: 9870 | J31: 12455 | K31: 9635
A32: EBITDA | B32: =B28+B27+B26 -> 6934 | C32: =C28+C27+C26 -> 7852 | D32: =D28+D27+D26 -> 9202 | E32: =E28+E27+E26 -> 10285 | F32: =F28+F27+F26 -> 11796 | G32: =G28+G27+G26 -> 13076 | H32: =H28+H27+H26 -> 14595 | I32: =I28+I27+I26 -> 15476 | ... K32: =K28+K27+K26 -> 19962
A33: EBIT | B33: =B28+B27 -> 6502 | C33: =C28+C27 -> 7332 | D33: =D28+D27 -> 8637 | E33: =E28+E27 -> 9283 | F33: =F28+F27 -> 10722 | G33: =G28+G27 -> 11985 | H33: =H28+H27 -> 13458 | I33: =I28+I27 -> 14260 | ... K33: =K28+K27 -> 18629
A40: Quarters
A41: Report Date | B41: 45291 | C41: 45382 | D41: 45473 | E41: 45565 | F41: 45657 | G41: 45747 | H41: 45838 | I41: 45930 | J41: 46022 | K41: 46112
A42: Sales | B42: 15567 | C42: 15210 | D42: 15707 | E42: 15926 | F42: 15556 | G42: 15190 | H42: 16514 | I42: 15919 | J42: 16441 | K42: 16351
A43: Expenses | B43: 11902 | C43: 11675 | D43: 11965 | E43: 12139 | F43: 11867 | G43: 11572 | H43: 12797 | I43: 12137 | J43: 12660 | K43: 12514
A44: Other Income | B44: 184 | C44: 309 | D44: 209 | E44: 203 | F44: 733 | G44: 149 | H44: 74 | I44: 269 | J44: 4048 | K44: 503
A45: Depreciation | B45: 313 | C45: 320 | D45: 329 | E45: 338 | F45: 318 | G45: 318 | H45: 361 | I45: 322 | J45: 337 | K45: 348
A46: Interest | B46: 91 | C46: 105 | D46: 93 | E46: 110 | F46: 109 | G46: 77 | H46: 127 | I46: 124 | J46: 88 | K46: 76
A47: Profit before tax | B47: 3445 | C47: 3419 | D47: 3529 | E47: 3542 | F47: 3995 | G47: 3372 | H47: 3303 | I47: 3605 | J47: 7404 | K47: 3916
A48: Tax | B48: 937 | C48: 858 | D48: 917 | E48: 947 | F48: 1006 | G48: 897 | H48: 535 | I48: 911 | J48: 801 | K48: 922
A49: Net profit | B49: 2509 | C49: 2558 | D49: 2610 | E49: 2591 | F49: 2984 | G49: 2464 | H49: 2756 | I49: 2685 | J49: 6607 | K49: 2992
A50: Operating Profit | B50: 3665 | C50: 3535 | D50: 3742 | E50: 3787 | F50: 3689 | G50: 3618 | H50: 3717 | I50: 3782 | J50: 3781 | K50: 3837
A55: BALANCE SHEET
A56: Report Date | B56: 42825 | C56: 43190 | D56: 43555 | E56: 43921 | F56: 44286 | G56: 44651 | H56: 45016 | I56: 45382 | J56: 45747 | K56: 46112
A57: Equity Share Capital | B57: 216 | C57: 216 | D57: 216 | E57: 216 | F57: 235 | G57: 235 | H57: 235 | I57: 235 | J57: 235 | K57: 235
A58: Reserves | B58: 6528 | C58: 7065 | D58: 7651 | E58: 8013 | F58: 47439 | G58: 48826 | H58: 50069 | I58: 50983 | J58: 49167 | K58: 48504
A59: Borrowings | B59: 277 | D59: 99 | G59: 1043 | H59: 1219 | I59: 1484 | J59: 1648 | K59: 1478
...

Sheet Financial Statements
B2: =_xlfn.CONCAT("Historical Financial Statement of ",'Data Sheet'!B1) -> Historical Financial Statement of HINDUSTAN UNILEVER LTD
B3: Year | C3: ='Data Sheet'!B16 -> 42825 | D3: ='Data Sheet'!C16 -> 43190 | E3: ='Data Sheet'!D16 -> 43555 | F3: ='Data Sheet'!E16 -> 43921 | G3: ='Data Sheet'!F16 -> 44286 | H3: ='Data Sheet'!G16 -> 44651 | I3: ='Data Sheet'!H16 -> 45016 | J3: ='Data Sheet'!I16 -> 45382 | ... L3: ='Data Sheet'!K16 -> 46112 | M3: ='Data Sheet'!K16+365 -> 46477 | N3: =M3+364 -> 46841 | O3: =N3+364 -> 47205 | P3: =O3+364 -> 47569 | Q3: =P3+364 -> 47933
A5: # | B5: Income Statement
B6: Revenue | C6: ='Data Sheet'!B17 -> 33162 | D6: ='Data Sheet'!C17 -> 35545 | E6: ='Data Sheet'!D17 -> 39310 | F6: ='Data Sheet'!E17 -> 39783 | G6: ='Data Sheet'!F17 -> 47028 | H6: ='Data Sheet'!G17 -> 52446 | I6: ='Data Sheet'!H17 -> 60580 | J6: ='Data Sheet'!I17 -> 61896 | ... L6: ='Data Sheet'!K17 -> 64468 | M6: =FORECAST(M$3,$C6:$L6,$C$3:$L$3) -> 70982.404 | N6: =FORECAST(N$3,$C6:$L6,$C$3:$L$3) -> 74865.76 | O6: =FORECAST(O$3,$C6:$L6,$C$3:$L$3) -> 78749.116 | P6: =FORECAST(P$3,$C6:$L6,$C$3:$L$3) -> 82632.472 | Q6: =FORECAST(Q$3,$C6:$L6,$C$3:$L$3) -> 86515.828
B7: Revenue Growth | D7: =(D6-C6)/C6 -> 0.071859357 | E7: =(E6-D6)/D6 -> 0.10592207 | F7: =(F6-E6)/E6 -> 0.012032562 | G7: =(G6-F6)/F6 -> 0.18211296 | H7: =(H6-G6)/G6 -> 0.11520796 | I7: =(I6-H6)/H6 -> 0.15509286 | J7: =(J6-I6)/I6 -> 0.021723341 | K7: =(K6-J6)/J6 -> -0.0091766835 | ... Q7: =(Q6-P6)/P6 -> 0.046995521
B9: COGS | C9: =SUM('Data Sheet'!B20:B22,'Data Sheet'!B18) - (1*'Data Sheet'!B19) -> 18675 | D9: =SUM('Data Sheet'!C20:C22,'Data Sheet'!C18) - (1*'Data Sheet'!C19) -> 19314 | E9: =SUM('Data Sheet'!D20:D22,'Data Sheet'!D18) - (1*'Data Sheet'!D19) -> 21081 | F9: =SUM('Data Sheet'!E20:E22,'Data Sheet'!E18) - (1*'Data Sheet'!E19) -> 20614 | G9: =SUM('Data Sheet'!F20:F22,'Data Sheet'!F18) - (1*'Data Sheet'!F19) -> 25301 | H9: =SUM('Data Sheet'!G20:G22,'Data Sheet'!G18) - (1*'Data Sheet'!G19) -> 29066 | I9: =SUM('Data Sheet'!H20:H22,'Data Sheet'!H18) - (1*'Data Sheet'!H19) -> 35381 | J9: =SUM('Data Sheet'!I20:I22,'Data Sheet'!I18) - (1*'Data Sheet'!I19) -> 33651 | ... L9: =SUM('Data Sheet'!K20:K22,'Data Sheet'!K18) - (1*'Data Sheet'!K19) -> 35634 | M9: =FORECAST(M$3,$C9:$L9,$C$3:$L$3) -> 39320.141 | N9: =FORECAST(N$3,$C9:$L9,$C$3:$L$3) -> 41512.394 | O9: =FORECAST(O$3,$C9:$L9,$C$3:$L$3) -> 43704.647 | P9: =FORECAST(P$3,$C9:$L9,$C$3:$L$3) -> 45896.9 | Q9: =FORECAST(Q$3,$C9:$L9,$C$3:$L$3) -> 48089.154
B10: Gross Profit | C10: =C6-C9 -> 14487 | D10: =D6-D9 -> 16231 | E10: =E6-E9 -> 18229 | F10: =F6-F9 -> 19169 | G10: =G6-G9 -> 21727 | H10: =H6-H9 -> 23380 | I10: =I6-I9 -> 25199 | J10: =J6-J9 -> 28245 | ... L10: =L6-L9 -> 28834 | M10: =FORECAST(M$3,$C10:$L10,$C$3:$L$3) -> 31662.264 | N10: =FORECAST(N$3,$C10:$L10,$C$3:$L$3) -> 33353.366 | O10: =FORECAST(O$3,$C10:$L10,$C$3:$L$3) -> 35044.469 | P10: =FORECAST(P$3,$C10:$L10,$C$3:$L$3) -> 36735.572 | Q10: =FORECAST(Q$3,$C10:$L10,$C$3:$L$3) -> 38426.675
B11: Gross Profit Margin | C11: =(C10/C6) -> 0.43685544 | D11: =(D10/D6) -> 0.45663244 | E11: =(E10/E6) -> 0.46372424 | F11: =(F10/F6) -> 0.48183898 | G11: =(G10/G6) -> 0.46200136 | H11: =(H10/H6) -> 0.44579186 | I11: =(I10/I6) -> 0.41596236 | J11: =(J10/J6) -> 0.45632997 | ... Q11: =(Q10/Q6) -> 0.44415774
B13: Operational Expenses | C13: =SUM('Data Sheet'!B23:B24) -> 8159 | D13: =SUM('Data Sheet'!C23:C24) -> 8732 | E13: =SUM('Data Sheet'!D23:D24) -> 9349 | F13: =SUM('Data Sheet'!E23:E24) -> 9308 | G13: =SUM('Data Sheet'!F23:F24) -> 10101 | H13: =SUM('Data Sheet'!G23:G24) -> 10523 | I13: =SUM('Data Sheet'!H23:H24) -> 11052 | J13: =SUM('Data Sheet'!I23:I24) -> 13586 | ... L13: =SUM('Data Sheet'!K23:K24) -> 13795 | M13: =FORECAST(M$3,$C13:$L13,$C$3:$L$3) -> 14378.169 | N13: =FORECAST(N$3,$C13:$L13,$C$3:$L$3) -> 15031.787 | O13: =FORECAST(O$3,$C13:$L13,$C$3:$L$3) -> 15685.404 | P13: =FORECAST(P$3,$C13:$L13,$C$3:$L$3) -> 16339.022 | Q13: =FORECAST(Q$3,$C13:$L13,$C$3:$L$3) -> 16992.64
B15: EBITDA | C15: =C10-C13 -> 6328 | D15: =D10-D13 -> 7499 | E15: =E10-E13 -> 8880 | F15: =F10-F13 -> 9861 | G15: =G10-G13 -> 11626 | H15: =H10-H13 -> 12857 | I15: =I10-I13 -> 14147 | J15: =J10-J13 -> 14659 | ... L15: =L10-L13 -> 15039 | M15: =FORECAST(M$3,$C15:$L15,$C$3:$L$3) -> 17284.095 | N15: =FORECAST(N$3,$C15:$L15,$C$3:$L$3) -> 18321.58 | O15: =FORECAST(O$3,$C15:$L15,$C$3:$L$3) -> 19359.065 | P15: =FORECAST(P$3,$C15:$L15,$C$3:$L$3) -> 20396.55 | Q15: =FORECAST(Q$3,$C15:$L15,$C$3:$L$3) -> 21434.035
B16: EBITDA Margins | C16: =C15/C6 -> 0.19082082 | D16: =D15/D6 -> 0.21097201 | E16: =E15/E6 -> 0.22589672 | F16: =F15/F6 -> 0.24786969 | G16: =G15/G6 -> 0.24721443 | H16: =H15/H6 -> 0.24514739 | I16: =I15/I6 -> 0.23352592 | J16: =J15/J6 -> 0.23683275 | ... Q16: =Q15/Q6 -> 0.24774698
B18: Depreciation and Amortization | C18: =SUM('Data Sheet'!B26) -> 432 | D18: =SUM('Data Sheet'!C26) -> 520 | E18: =SUM('Data Sheet'!D26) -> 565 | F18: =SUM('Data Sheet'!E26) -> 1002 | G18: =SUM('Data Sheet'!F26) -> 1074 | H18: =SUM('Data Sheet'!G26) -> 1091 | I18: =SUM('Data Sheet'!H26) -> 1137 | J18: =SUM('Data Sheet'!I26) -> 1216 | ... L18: =SUM('Data Sheet'!K26) -> 1333 | M18: =FORECAST(M$3,$C18:$L18,$C$3:$L$3) -> 1526.1118 | N18: =FORECAST(N$3,$C18:$L18,$C$3:$L$3) -> 1628.2912 | O18: =FORECAST(O$3,$C18:$L18,$C$3:$L$3) -> 1730.4707 | P18: =FORECAST(P$3,$C18:$L18,$C$3:$L$3) -> 1832.6502 | Q18: =FORECAST(Q$3,$C18:$L18,$C$3:$L$3) -> 1934.8297
B20: EBIT | C20: =C15-C18 -> 5896 | D20: =D15-D18 -> 6979 | E20: =E15-E18 -> 8315 | F20: =F15-F18 -> 8859 | G20: =G15-G18 -> 10552 | H20: =H15-H18 -> 11766 | I20: =I15-I18 -> 13010 | J20: =J15-J18 -> 13443 | ... L20: =L15-L18 -> 13706 | M20: =FORECAST(M$3,$C20:$L20,$C$3:$L$3) -> 15757.983 | N20: =FORECAST(N$3,$C20:$L20,$C$3:$L$3) -> 16693.288 | O20: =FORECAST(O$3,$C20:$L20,$C$3:$L$3) -> 17628.594 | P20: =FORECAST(P$3,$C20:$L20,$C$3:$L$3) -> 18563.9 | Q20: =FORECAST(Q$3,$C20:$L20,$C$3:$L$3) -> 19499.205
B21: EBIT Margins | C21: =C20/C6 -> 0.17779386 | D21: =D20/D6 -> 0.19634266 | E21: =E20/E6 -> 0.21152379 | F21: =F20/F6 -> 0.22268306 | G21: =G20/G6 -> 0.22437697 | H21: =H20/H6 -> 0.22434504 | I21: =I20/I6 -> 0.21475735 | J21: =J20/J6 -> 0.21718689 | ... Q21: =Q20/Q6 -> 0.2253831
B23: Interest | C23: ='Data Sheet'!B27 -> 35 | D23: ='Data Sheet'!C27 -> 26 | E23: ='Data Sheet'!D27 -> 33 | F23: ='Data Sheet'!E27 -> 118 | G23: ='Data Sheet'!F27 -> 117 | H23: ='Data Sheet'!G27 -> 106 | I23: ='Data Sheet'!H27 -> 114 | J23: ='Data Sheet'!I27 -> 334 | ... L23: ='Data Sheet'!K27 -> 410 | M23: =FORECAST(M$3,$C23:$L23,$C$3:$L$3) -> 412.10221 | N23: =FORECAST(N$3,$C23:$L23,$C$3:$L$3) -> 456.44954 | O23: =FORECAST(O$3,$C23:$L23,$C$3:$L$3) -> 500.79686 | P23: =FORECAST(P$3,$C23:$L23,$C$3:$L$3) -> 545.14419 | Q23: =FORECAST(Q$3,$C23:$L23,$C$3:$L$3) -> 589.49151
B25: EBT | C25: =C20-C23 -> 5861 | D25: =D20-D23 -> 6953 | E25: =E20-E23 -> 8282 | F25: =F20-F23 -> 8741 | G25: =G20-G23 -> 10435 | H25: =H20-H23 -> 11660 | I25: =I20-I23 -> 12896 | J25: =J20-J23 -> 13109 | ... L25: =L20-L23 -> 13296 | M25: =FORECAST(M$3,$C25:$L25,$C$3:$L$3) -> 15345.881 | N25: =FORECAST(N$3,$C25:$L25,$C$3:$L$3) -> 16236.839 | O25: =FORECAST(O$3,$C25:$L25,$C$3:$L$3) -> 17127.797 | P25: =FORECAST(P$3,$C25:$L25,$C$3:$L$3) -> 18018.756 | Q25: =FORECAST(Q$3,$C25:$L25,$C$3:$L$3) -> 18909.714
B26: EBT Margins | C26: =C25/C6 -> 0.17673844 | D26: =D25/D6 -> 0.1956112 | E26: =E25/E6 -> 0.2106843 | F26: =F25/F6 -> 0.21971696 | G26: =G25/G6 -> 0.22188909 | H26: =H25/H6 -> 0.22232391 | I26: =I25/I6 -> 0.21287554 | J26: =J25/J6 -> 0.21179075 | ... Q26: =Q25/Q6 -> 0.21856941
B28: Tax | C28: ='Data Sheet'!B29 -> 1977 | D28: ='Data Sheet'!C29 -> 2079 | E28: ='Data Sheet'!D29 -> 2544 | F28: ='Data Sheet'!E29 -> 2409 | G28: ='Data Sheet'!F29 -> 2606 | H28: ='Data Sheet'!G29 -> 2987 | I28: ='Data Sheet'!H29 -> 3201 | J28: ='Data Sheet'!I29 -> 3644 | ... L28: ='Data Sheet'!K29 -> 3160 | M28: =FORECAST(M$3,$C28:$L28,$C$3:$L$3) -> 3854.8744 | N28: =FORECAST(N$3,$C28:$L28,$C$3:$L$3) -> 4039.6154 | O28: =FORECAST(O$3,$C28:$L28,$C$3:$L$3) -> 4224.3564 | P28: =FORECAST(P$3,$C28:$L28,$C$3:$L$3) -> 4409.0973 | Q28: =FORECAST(Q$3,$C28:$L28,$C$3:$L$3) -> 4593.8383
B30: Net Profit | C30: =C25-C28 -> 3884 | D30: =D25-D28 -> 4874 | E30: =E25-E28 -> 5738 | F30: =F25-F28 -> 6332 | G30: =G25-G28 -> 7829 | H30: =H25-H28 -> 8673 | I30: =I25-I28 -> 9695 | J30: =J25-J28 -> 9465 | ... L30: =L25-L28 -> 10136 | M30: =FORECAST(M$3,$C30:$L30,$C$3:$L$3) -> 11491.006 | N30: =FORECAST(N$3,$C30:$L30,$C$3:$L$3) -> 12197.224 | O30: =FORECAST(O$3,$C30:$L30,$C$3:$L$3) -> 12903.441 | P30: =FORECAST(P$3,$C30:$L30,$C$3:$L$3) -> 13609.658 | Q30: =FORECAST(Q$3,$C30:$L30,$C$3:$L$3) -> 14315.875
B31: Net Profit Margins | C31: =C30/C6 -> 0.11712201 | D31: =D30/D6 -> 0.13712196 | E31: =E30/E6 -> 0.14596795 | F31: =F30/F6 -> 0.15916346 | G31: =G30/G6 -> 0.16647529 | H31: =H30/H6 -> 0.16537009 | I31: =I30/I6 -> 0.16003632 | J31: =J30/J6 -> 0.1529178 | ... Q31: =Q30/Q6 -> 0.16547117
A34: # | B34: Balance Sheet
B35: Equity
B36: Equity Share Capital | C36: ='Data Sheet'!B57 -> 216 | D36: ='Data Sheet'!C57 -> 216 | E36: ='Data Sheet'!D57 -> 216 | F36: ='Data Sheet'!E57 -> 216 | G36: ='Data Sheet'!F57 -> 235 | H36: ='Data Sheet'!G57 -> 235 | I36: ='Data Sheet'!H57 -> 235 | J36: ='Data Sheet'!I57 -> 235 | ... L36: ='Data Sheet'!K57 -> 235 | M36: =FORECAST(M$3,$C36:$L36,$C$3:$L$3) -> 242.59678 | N36: =FORECAST(N$3,$C36:$L36,$C$3:$L$3) -> 245.35089 | O36: =FORECAST(O$3,$C36:$L36,$C$3:$L$3) -> 248.105 | P36: =FORECAST(P$3,$C36:$L36,$C$3:$L$3) -> 250.85911 | Q36: =FORECAST(Q$3,$C36:$L36,$C$3:$L$3) -> 253.61322
B37: Reserves | C37: ='Data Sheet'!B58 -> 6528 | D37: ='Data Sheet'!C58 -> 7065 | E37: ='Data Sheet'!D58 -> 7651 | F37: ='Data Sheet'!E58 -> 8013 | G37: ='Data Sheet'!F58 -> 47439 | H37: ='Data Sheet'!G58 -> 48826 | I37: ='Data Sheet'!H58 -> 50069 | J37: ='Data Sheet'!I58 -> 50983 | ... L37: ='Data Sheet'!K58 -> 48504 | M37: =FORECAST(M$3,$C37:$L37,$C$3:$L$3) -> 66307.82 | N37: =FORECAST(N$3,$C37:$L37,$C$3:$L$3) -> 72448.487 | O37: =FORECAST(O$3,$C37:$L37,$C$3:$L$3) -> 78589.153 | P37: =FORECAST(P$3,$C37:$L37,$C$3:$L$3) -> 84729.819 | Q37: =FORECAST(Q$3,$C37:$L37,$C$3:$L$3) -> 90870.486
B38: Borrowings | C38: ='Data Sheet'!B59 -> 277 | D38: ='Data Sheet'!C59 -> 0 | E38: ='Data Sheet'!D59 -> 99 | F38: ='Data Sheet'!E59 -> 0 | G38: ='Data Sheet'!F59 -> 0 | H38: ='Data Sheet'!G59 -> 1043 | I38: ='Data Sheet'!H59 -> 1219 | J38: ='Data Sheet'!I59 -> 1484 | ... L38: ='Data Sheet'!K59 -> 1478 | M38: =FORECAST(M$3,$C38:$L38,$C$3:$L$3) -> 1856.8915 | N38: =FORECAST(N$3,$C38:$L38,$C$3:$L$3) -> 2062.0602 | O38: =FORECAST(O$3,$C38:$L38,$C$3:$L$3) -> 2267.2288 | P38: =FORECAST(P$3,$C38:$L38,$C$3:$L$3) -> 2472.3975 | Q38: =FORECAST(Q$3,$C38:$L38,$C$3:$L$3) -> 2677.5662
B39: Other Liabilities | C39: ='Data Sheet'!B60 -> 2499 | D39: ='Data Sheet'!C60 -> 3411 | E39: ='Data Sheet'!D60 -> 3457 | F39: ='Data Sheet'!E60 -> 4389 | G39: ='Data Sheet'!F60 -> 12264 | H39: ='Data Sheet'!G60 -> 11334 | I39: ='Data Sheet'!H60 -> 11980 | J39: ='Data Sheet'!I60 -> 15301 | ... L39: ='Data Sheet'!K60 -> 16196 | M39: =FORECAST(M$3,$C39:$L39,$C$3:$L$3) -> 19929.251 | N39: =FORECAST(N$3,$C39:$L39,$C$3:$L$3) -> 21759.01 | O39: =FORECAST(O$3,$C39:$L39,$C$3:$L$3) -> 23588.77 | P39: =FORECAST(P$3,$C39:$L39,$C$3:$L$3) -> 25418.529 | Q39: =FORECAST(Q$3,$C39:$L39,$C$3:$L$3) -> 27248.288
B40: Trade Payables | C40: ='Data Sheet'!B61 -> 6186 | D40: ='Data Sheet'!C61 -> 7170 | E40: ='Data Sheet'!D61 -> 7206 | F40: ='Data Sheet'!E61 -> 7535 | G40: ='Data Sheet'!F61 -> 8802 | H40: ='Data Sheet'!G61 -> 9068 | I40: ='Data Sheet'!H61 -> 9574 | J40: ='Data Sheet'!I61 -> 10486 | ... L40: ='Data Sheet'!K61 -> 13325 | M40: =FORECAST(M$3,$C40:$L40,$C$3:$L$3) -> 12934.192 | N40: =FORECAST(N$3,$C40:$L40,$C$3:$L$3) -> 13635.097 | O40: =FORECAST(O$3,$C40:$L40,$C$3:$L$3) -> 14336.001 | P40: =FORECAST(P$3,$C40:$L40,$C$3:$L$3) -> 15036.906 | Q40: =FORECAST(Q$3,$C40:$L40,$C$3:$L$3) -> 15737.811
B41: Total Equity + Liabilities | C41: =SUM(C36:C40) -> 15706 | D41: =SUM(D36:D40) -> 17862 | E41: =SUM(E36:E40) -> 18629 | F41: =SUM(F36:F40) -> 20153 | G41: =SUM(G36:G40) -> 68740 | H41: =SUM(H36:H40) -> 70506 | I41: =SUM(I36:I40) -> 73077 | J41: =SUM(J36:J40) -> 78489 | ... Q41: =SUM(Q36:Q40) -> 136787.76
B43: Net Block | C43: ='Data Sheet'!B63 -> 4419 | D43: ='Data Sheet'!C63 -> 4528 | E43: ='Data Sheet'!D63 -> 4715 | F43: ='Data Sheet'!E63 -> 5479 | G43: ='Data Sheet'!F63 -> 51443 | H43: ='Data Sheet'!G63 -> 51473 | I43: ='Data Sheet'!H63 -> 52678 | J43: ='Data Sheet'!I63 -> 53744 | ... L43: ='Data Sheet'!K63 -> 57428 | M43: =FORECAST(M$3,$C43:$L43,$C$3:$L$3) -> 74432.432 | N43: =FORECAST(N$3,$C43:$L43,$C$3:$L$3) -> 81755.607 | O43: =FORECAST(O$3,$C43:$L43,$C$3:$L$3) -> 89078.782 | P43: =FORECAST(P$3,$C43:$L43,$C$3:$L$3) -> 96401.956 | Q43: =FORECAST(Q$3,$C43:$L43,$C$3:$L$3) -> 103725.13
B44: Capital work in progress | C44: ='Data Sheet'!B64 -> 229 | D44: ='Data Sheet'!C64 -> 461 | E44: ='Data Sheet'!D64 -> 406 | F44: ='Data Sheet'!E64 -> 597 | G44: ='Data Sheet'!F64 -> 745 | H44: ='Data Sheet'!G64 -> 1313 | I44: ='Data Sheet'!H64 -> 1132 | J44: ='Data Sheet'!I64 -> 1025 | ... L44: ='Data Sheet'!K64 -> 880 | M44: =FORECAST(M$3,$C44:$L44,$C$3:$L$3) -> 1278.3516 | N44: =FORECAST(N$3,$C44:$L44,$C$3:$L$3) -> 1368.7221 | O44: =FORECAST(O$3,$C44:$L44,$C$3:$L$3) -> 1459.0926 | P44: =FORECAST(P$3,$C44:$L44,$C$3:$L$3) -> 1549.4631 | Q44: =FORECAST(Q$3,$C44:$L44,$C$3:$L$3) -> 1639.8336
B45: Investments | C45: ='Data Sheet'!B65 -> 3794 | D45: ='Data Sheet'!C65 -> 2873 | E45: ='Data Sheet'!D65 -> 2716 | F45: ='Data Sheet'!E65 -> 1255 | G45: ='Data Sheet'!F65 -> 2709 | H45: ='Data Sheet'!G65 -> 3521 | I45: ='Data Sheet'!H65 -> 2882 | J45: ='Data Sheet'!I65 -> 4625 | ... L45: ='Data Sheet'!K65 -> 4359 | M45: =FORECAST(M$3,$C45:$L45,$C$3:$L$3) -> 4150.2863 | N45: =FORECAST(N$3,$C45:$L45,$C$3:$L$3) -> 4312.6476 | O45: =FORECAST(O$3,$C45:$L45,$C$3:$L$3) -> 4475.0089 | P45: =FORECAST(P$3,$C45:$L45,$C$3:$L$3) -> 4637.3701 | Q45: =FORECAST(Q$3,$C45:$L45,$C$3:$L$3) -> 4799.7314
B46: Other Assets | C46: ='Data Sheet'!B66-(SUM('Data Sheet'!B68:B70)) -> 1810 | D46: ='Data Sheet'!C66-(SUM('Data Sheet'!C68:C70)) -> 2692 | E46: ='Data Sheet'!D66-(SUM('Data Sheet'!D68:D70)) -> 2645 | F46: ='Data Sheet'!E66-(SUM('Data Sheet'!E68:E70)) -> 3793 | G46: ='Data Sheet'!F66-(SUM('Data Sheet'!F68:F70)) -> 4035 | H46: ='Data Sheet'!G66-(SUM('Data Sheet'!G68:G70)) -> 4021 | I46: ='Data Sheet'!H66-(SUM('Data Sheet'!H68:H70)) -> 4377 | J46: ='Data Sheet'!I66-(SUM('Data Sheet'!I68:I70)) -> 4517 | ... L46: ='Data Sheet'!K66-(SUM('Data Sheet'!K68:K70)) -> 5655 | M46: =FORECAST(M$3,$C46:$L46,$C$3:$L$3) -> 5889.7525 | N46: =FORECAST(N$3,$C46:$L46,$C$3:$L$3) -> 6260.0325 | O46: =FORECAST(O$3,$C46:$L46,$C$3:$L$3) -> 6630.3126 | P46: =FORECAST(P$3,$C46:$L46,$C$3:$L$3) -> 7000.5927 | Q46: =FORECAST(Q$3,$C46:$L46,$C$3:$L$3) -> 7370.8727
B47: Total Non Current Assets | C47: =SUM(C43:C46) -> 10252 | D47: =SUM(D43:D46) -> 10554 | E47: =SUM(E43:E46) -> 10482 | F47: =SUM(F43:F46) -> 11124 | G47: =SUM(G43:G46) -> 58932 | H47: =SUM(H43:H46) -> 60328 | I47: =SUM(I43:I46) -> 61069 | J47: =SUM(J43:J46) -> 63911 | ... Q47: =SUM(Q43:Q46) -> 117535.57
B48: Receivables | C48: ='Data Sheet'!B68 -> 1085 | D48: ='Data Sheet'!C68 -> 1310 | E48: ='Data Sheet'!D68 -> 1816 | F48: ='Data Sheet'!E68 -> 1149 | G48: ='Data Sheet'!F68 -> 1758 | H48: ='Data Sheet'!G68 -> 2236 | I48: ='Data Sheet'!H68 -> 3079 | J48: ='Data Sheet'!I68 -> 2997 | ... L48: ='Data Sheet'!K68 -> 3379 | M48: =FORECAST(M$3,$C48:$L48,$C$3:$L$3) -> 3941.7874 | N48: =FORECAST(N$3,$C48:$L48,$C$3:$L$3) -> 4246.0699 | O48: =FORECAST(O$3,$C48:$L48,$C$3:$L$3) -> 4550.3524 | P48: =FORECAST(P$3,$C48:$L48,$C$3:$L$3) -> 4854.6349 | Q48: =FORECAST(Q$3,$C48:$L48,$C$3:$L$3) -> 5158.9174
B49: Inventory | C49: ='Data Sheet'!B69 -> 2541 | D49: ='Data Sheet'!C69 -> 2513 | E49: ='Data Sheet'!D69 -> 2574 | F49: ='Data Sheet'!E69 -> 2767 | G49: ='Data Sheet'!F69 -> 3579 | H49: ='Data Sheet'!G69 -> 4096 | I49: ='Data Sheet'!H69 -> 4251 | J49: ='Data Sheet'!I69 -> 4022 | ... L49: ='Data Sheet'!K69 -> 4789 | M49: =FORECAST(M$3,$C49:$L49,$C$3:$L$3) -> 5079.5218 | N49: =FORECAST(N$3,$C49:$L49,$C$3:$L$3) -> 5355.8649 | O49: =FORECAST(O$3,$C49:$L49,$C$3:$L$3) -> 5632.208 | P49: =FORECAST(P$3,$C49:$L49,$C$3:$L$3) -> 5908.5511 | Q49: =FORECAST(Q$3,$C49:$L49,$C$3:$L$3) -> 6184.8942
B50: Cash & Bank | C50: ='Data Sheet'!B70 -> 1828 | D50: ='Data Sheet'!C70 -> 3485 | E50: ='Data Sheet'!D70 -> 3757 | F50: ='Data Sheet'!E70 -> 5113 | G50: ='Data Sheet'!F70 -> 4471 | H50: ='Data Sheet'!G70 -> 3846 | I50: ='Data Sheet'!H70 -> 4678 | J50: ='Data Sheet'!I70 -> 7559 | ... L50: ='Data Sheet'!K70 -> 3248 | M50: =FORECAST(M$3,$C50:$L50,$C$3:$L$3) -> 6498.6198 | N50: =FORECAST(N$3,$C50:$L50,$C$3:$L$3) -> 6851.0609 | O50: =FORECAST(O$3,$C50:$L50,$C$3:$L$3) -> 7203.502 | P50: =FORECAST(P$3,$C50:$L50,$C$3:$L$3) -> 7555.9431 | Q50: =FORECAST(Q$3,$C50:$L50,$C$3:$L$3) -> 7908.3842
B51: Total Current Assets | C51: =SUM(C48:C50) -> 5454 | D51: =SUM(D48:D50) -> 7308 | E51: =SUM(E48:E50) -> 8147 | F51: =SUM(F48:F50) -> 9029 | G51: =SUM(G48:G50) -> 9808 | H51: =SUM(H48:H50) -> 10178 | I51: =SUM(I48:I50) -> 12008 | J51: =SUM(J48:J50) -> 14578 | ... Q51: =SUM(Q48:Q50) -> 19252.196
B53: Total Assets | C53: =C47+C51 -> 15706 | D53: =D47+D51 -> 17862 | E53: =E47+E51 -> 18629 | F53: =F47+F51 -> 20153 | G53: =G47+G51 -> 68740 | H53: =H47+H51 -> 70506 | I53: =I47+I51 -> 73077 | J53: =J47+J51 -> 78489 | ... Q53: =Q47+Q51 -> 136787.76
A57: # | B57: Cash Flow Statement
B58: Cash Flow from Operating Activities:
...

Sheet Sheet2
C1: 42795 | D1: 43160 | E1: 43525 | F1: 43891 | G1: 44256 | H1: 44621 | I1: 44986 | J1: 45352 | K1: 45717 | L1: 46082
B3: Profit from operations | C3: 6512 | D3: 7485 | E3: 8909 | F3: 9723 | G3: 11672 | H3: 12829 | I3: 14089 | J3: 14537 | K3: 14942 | L3: 15153
B4: Receivables | C4: 173 | D4: 0 | E4: 0 | F4: 0 | G4: 0 | H4: 0 | I4: 0 | J4: 0 | K4: 0 | L4: 0
B5: Inventory | C5: 37 | D5: -146 | E5: -195 | F5: -331 | G5: -543 | H5: -758 | I5: -339 | J5: 74 | K5: -584 | L5: -692
B6: Payables | C6: 501 | D6: 0 | E6: 0 | F6: 0 | G6: 0 | H6: 0 | I6: 0 | J6: 0 | K6: 0 | L6: 0
B7: Loans Advances | C7: 0 | D7: 0 | E7: 0 | F7: 0 | G7: 0 | H7: 0 | I7: 0 | J7: 0 | K7: 0 | L7: 0
B8: Operating Deposits | C8: -46 | D8: 0 | E8: 0 | F8: 0 | G8: 0 | H8: 0 | I8: 0 | J8: 0 | K8: 0 | L8: 0
B9: Other WC items | C9: -99 | D9: 982 | E9: -147 | F9: 742 | G9: 442 | H9: -242 | I9: -621 | J9: 1239 | K9: -204 | L9: 1378
B10: Working capital changes | C10: 566 | D10: 836 | E10: -342 | F10: 411 | G10: -101 | H10: -1000 | I10: -960 | J10: 1313 | K10: -788 | L10: 686
B11: Direct taxes | C11: -1859 | D11: -2264 | E11: -2767 | F11: -2505 | G11: -2407 | H11: -2784 | I11: -3138 | J11: -381 | K11: -2268 | L11: -4840
B12: Other operating items | C12: -21 | D12: 0 | E12: 0 | F12: 0 | G12: 0 | H12: 0 | I12: 0 | J12: 0 | K12: 0 | L12: 0
B13: Exceptional CF items | C13: -13 | D13: 2 | E13: 0 | F13: -6 | G13: -1 | H13: 3 | I13: 0 | J13: 0 | K13: 0 | L13: 0
B14: Cash from Operating Activity - | C14: 5185 | D14: 6059 | E14: 5800 | F14: 7623 | G14: 9163 | H14: 9048 | I14: 9991 | J14: 15469 | K14: 11886 | L14: 10999
... B37: Free Cash Flow | C37: 4248 | D37: 5196 | E37: 5046 | F37: 6813 | G37: 5097 | H37: 7995 | I37: 8980 | J37: 14012 | K37: 10624 | L37: 9667
B38: CFO/OP

Sheet Common Size Statement
B1: Common Size Statement of Income for Hindustan Unilever
C2: 42825 | D2: 43190 | E2: 43555 | F2: 43921 | G2: 44286 | H2: 44651 | I2: 45016 | J2: 45382 | K2: 45747 | L2: 46112
B3: Sales | C3: ='Data Sheet'!B17/'Data Sheet'!B$17 -> 1 | D3: ='Data Sheet'!C17/'Data Sheet'!C$17 -> 1 | E3: ='Data Sheet'!D17/'Data Sheet'!D$17 -> 1 | F3: ='Data Sheet'!E17/'Data Sheet'!E$17 -> 1 | G3: ='Data Sheet'!F17/'Data Sheet'!F$17 -> 1 | H3: ='Data Sheet'!G17/'Data Sheet'!G$17 -> 1 | I3: ='Data Sheet'!H17/'Data Sheet'!H$17 -> 1 | J3: ='Data Sheet'!I17/'Data Sheet'!I$17 -> 1 | ... L3: ='Data Sheet'!K17/'Data Sheet'!K$17 -> 1
B4: Raw Material Cost | C4: ='Data Sheet'!B18/'Data Sheet'!B$17 -> 0.41028888 | D4: ='Data Sheet'!C18/'Data Sheet'!C$17 -> 0.400422 | E4: ='Data Sheet'!D18/'Data Sheet'!D$17 -> 0.4030781 | F4: ='Data Sheet'!E18/'Data Sheet'!E$17 -> 0.39456552 | G4: ='Data Sheet'!F18/'Data Sheet'!F$17 -> 0.42827677 | H4: ='Data Sheet'!G18/'Data Sheet'!G$17 -> 0.43608664 | I4: ='Data Sheet'!H18/'Data Sheet'!H$17 -> 0.46924728 | J4: ='Data Sheet'!I18/'Data Sheet'!I$17 -> 0.4333398 | ... L4: ='Data Sheet'!K18/'Data Sheet'!K$17 -> 0.45228641
B5: Change in Inventory | C5: ='Data Sheet'!B19/'Data Sheet'!B$17 -> -0.0043423195 | D5: ='Data Sheet'!C19/'Data Sheet'!C$17 -> 0.0020256014 | E5: ='Data Sheet'!D19/'Data Sheet'!D$17 -> -0.00030526584 | F5: ='Data Sheet'!E19/'Data Sheet'!E$17 -> 0.0027147274 | G5: ='Data Sheet'!F19/'Data Sheet'!F$17 -> 0.0086118908 | H5: ='Data Sheet'!G19/'Data Sheet'!G$17 -> 0.00041947908 | I5: ='Data Sheet'!H19/'Data Sheet'!H$17 -> 0.0012380324 | J5: ='Data Sheet'!I19/'Data Sheet'!I$17 -> 0.00017771746 | ... L5: ='Data Sheet'!K19/'Data Sheet'!K$17 -> 0.0066544642
B6: Power and Fuel | C6: ='Data Sheet'!B20/'Data Sheet'!B$17 -> 0.008895724 | D6: ='Data Sheet'!C20/'Data Sheet'!C$17 -> 0.0082993389 | E6: ='Data Sheet'!D20/'Data Sheet'!D$17 -> 0.0078351564 | F6: ='Data Sheet'!E20/'Data Sheet'!E$17 -> 0.0075157731 | G6: ='Data Sheet'!F20/'Data Sheet'!F$17 -> 0.0072084715 | H6: ='Data Sheet'!G20/'Data Sheet'!G$17 -> 0.0060633795 | I6: ='Data Sheet'!H20/'Data Sheet'!H$17 -> 0.0063387257 | J6: ='Data Sheet'!I20/'Data Sheet'!I$17 -> 0.0072056353 | ... L6: ='Data Sheet'!K20/'Data Sheet'!K$17 -> 0.0066079295
B7: Other Mfr. Exp | C7: ='Data Sheet'!B21/'Data Sheet'!B$17 -> 0.087057475 | D7: ='Data Sheet'!C21/'Data Sheet'!C$17 -> 0.08434379 | E7: ='Data Sheet'!D21/'Data Sheet'!D$17 -> 0.077359451 | F7: ='Data Sheet'!E21/'Data Sheet'!E$17 -> 0.073046276 | G7: ='Data Sheet'!F21/'Data Sheet'!F$17 -> 0.060984945 | H7: ='Data Sheet'!G21/'Data Sheet'!G$17 -> 0.063951493 | I7: ='Data Sheet'!H21/'Data Sheet'!H$17 -> 0.062578409 | J7: ='Data Sheet'!I21/'Data Sheet'!I$17 -> 0.05468851 | ... L7: ='Data Sheet'!K21/'Data Sheet'!K$17 -> 0.051250233
B8: Employee Cost | C8: ='Data Sheet'!B22/'Data Sheet'!B$17 -> 0.052560159 | D8: ='Data Sheet'!C22/'Data Sheet'!C$17 -> 0.052328035 | E8: ='Data Sheet'!D22/'Data Sheet'!D$17 -> 0.047697787 | F8: ='Data Sheet'!E22/'Data Sheet'!E$17 -> 0.045748184 | G8: ='Data Sheet'!F22/'Data Sheet'!F$17 -> 0.050140342 | H8: ='Data Sheet'!G22/'Data Sheet'!G$17 -> 0.048526103 | I8: ='Data Sheet'!H22/'Data Sheet'!H$17 -> 0.047111258 | J8: ='Data Sheet'!I22/'Data Sheet'!I$17 -> 0.048613804 | ... L8: ='Data Sheet'!K22/'Data Sheet'!K$17 -> 0.04924924
B9: Selling and admin | C9: ='Data Sheet'!B23/'Data Sheet'!B$17 -> 0.20170677 | D9: ='Data Sheet'!C23/'Data Sheet'!C$17 -> 0.20402307 | E9: ='Data Sheet'!D23/'Data Sheet'!D$17 -> 0.19832104 | F9: ='Data Sheet'!E23/'Data Sheet'!E$17 -> 0.1915391 | G9: ='Data Sheet'!F23/'Data Sheet'!F$17 -> 0.16811261 | H9: ='Data Sheet'!G23/'Data Sheet'!G$17 -> 0.15566487 | I9: ='Data Sheet'!H23/'Data Sheet'!H$17 -> 0.14501486 | J9: ='Data Sheet'!I23/'Data Sheet'!I$17 -> 0.17416311 | ... L9: ='Data Sheet'!K23/'Data Sheet'!K$17 -> 0.16665633
B10: Other Expenses | C10: ='Data Sheet'!B24/'Data Sheet'!B$17 -> 0.044327845 | D10: ='Data Sheet'!C24/'Data Sheet'!C$17 -> 0.041637361 | E10: ='Data Sheet'!D24/'Data Sheet'!D$17 -> 0.039506487 | F10: ='Data Sheet'!E24/'Data Sheet'!E$17 -> 0.042430184 | G10: ='Data Sheet'!F24/'Data Sheet'!F$17 -> 0.046674322 | H10: ='Data Sheet'!G24/'Data Sheet'!G$17 -> 0.044979598 | I10: ='Data Sheet'!H24/'Data Sheet'!H$17 -> 0.037421591 | J10: ='Data Sheet'!I24/'Data Sheet'!I$17 -> 0.045334109 | ... L10: ='Data Sheet'!K24/'Data Sheet'!K$17 -> 0.047325805
B11: Other Income | C11: ='Data Sheet'!B25/'Data Sheet'!B$17 -> 0.018273928 | D11: ='Data Sheet'!C25/'Data Sheet'!C$17 -> 0.0099310733 | E11: ='Data Sheet'!D25/'Data Sheet'!D$17 -> 0.0081912999 | F11: ='Data Sheet'!E25/'Data Sheet'!E$17 -> 0.010657819 | G11: ='Data Sheet'!F25/'Data Sheet'!F$17 -> 0.0036148677 | H11: ='Data Sheet'!G25/'Data Sheet'!G$17 -> 0.0041757236 | I11: ='Data Sheet'!H25/'Data Sheet'!H$17 -> 0.0073951799 | J11: ='Data Sheet'!I25/'Data Sheet'!I$17 -> 0.013199561 | ... L11: ='Data Sheet'!K25/'Data Sheet'!K$17 -> 0.076363467
B12: Depreciation | C12: ='Data Sheet'!B26/'Data Sheet'!B$17 -> 0.013026959 | D12: ='Data Sheet'!C26/'Data Sheet'!C$17 -> 0.014629343 | E12: ='Data Sheet'!D26/'Data Sheet'!D$17 -> 0.014372933 | F12: ='Data Sheet'!E26/'Data Sheet'!E$17 -> 0.025186638 | G12: ='Data Sheet'!F26/'Data Sheet'!F$17 -> 0.022837459 | H12: ='Data Sheet'!G26/'Data Sheet'!G$17 -> 0.020802349 | I12: ='Data Sheet'!H26/'Data Sheet'!H$17 -> 0.01876857 | J12: ='Data Sheet'!I26/'Data Sheet'!I$17 -> 0.019645858 | ... L12: ='Data Sheet'!K26/'Data Sheet'!K$17 -> 0.020676925
B13: Interest | C13: ='Data Sheet'!B27/'Data Sheet'!B$17 -> 0.0010554249 | D13: ='Data Sheet'!C27/'Data Sheet'!C$17 -> 0.00073146715 | E13: ='Data Sheet'!D27/'Data Sheet'!D$17 -> 0.00083948105 | F13: ='Data Sheet'!E27/'Data Sheet'!E$17 -> 0.002966091 | G13: ='Data Sheet'!F27/'Data Sheet'!F$17 -> 0.0024878796 | H13: ='Data Sheet'!G27/'Data Sheet'!G$17 -> 0.0020211265 | I13: ='Data Sheet'!H27/'Data Sheet'!H$17 -> 0.0018818092 | J13: ='Data Sheet'!I27/'Data Sheet'!I$17 -> 0.0053961484 | ... L13: ='Data Sheet'!K27/'Data Sheet'!K$17 -> 0.0063597444
B14: Profit before tax | C14: ='Data Sheet'!B28/'Data Sheet'!B$17 -> 0.19501236 | D14: ='Data Sheet'!C28/'Data Sheet'!C$17 -> 0.20554227 | E14: ='Data Sheet'!D28/'Data Sheet'!D$17 -> 0.2188756 | F14: ='Data Sheet'!E28/'Data Sheet'!E$17 -> 0.23037478 | G14: ='Data Sheet'!F28/'Data Sheet'!F$17 -> 0.22550396 | H14: ='Data Sheet'!G28/'Data Sheet'!G$17 -> 0.22649964 | I14: ='Data Sheet'!H28/'Data Sheet'!H$17 -> 0.22027072 | J14: ='Data Sheet'!I28/'Data Sheet'!I$17 -> 0.22499031 | ... L14: ='Data Sheet'!K28/'Data Sheet'!K$17 -> 0.28260532
... B19: EBIT | C19: ='Data Sheet'!B33/'Data Sheet'!B$17 -> 0.19606779 | D19: ='Data Sheet'!C33/'Data Sheet'!C$17 -> 0.20627374 | E19: ='Data Sheet'!D33/'Data Sheet'!D$17 -> 0.21971509 | F19: ='Data Sheet'!E33/'Data Sheet'!E$17 -> 0.23334087 | G19: ='Data Sheet'!F33/'Data Sheet'!F$17 -> 0.22799183 | H19: ='Data Sheet'!G33/'Data Sheet'!G$17 -> 0.22852076 | I19: ='Data Sheet'!H33/'Data Sheet'!H$17 -> 0.22215253 | J19: ='Data Sheet'!I33/'Data Sheet'!I$17 -> 0.23038645 | ... L19: ='Data Sheet'!K33/'Data Sheet'!K$17 -> 0.28896507
B22: Common Size Balance Sheet for Hindustan Unilever
B23: Equity
B24: Equity Share Capital | C24: ='Financial Statements'!C36/'Financial Statements'!C$41 -> 0.013752706 | D24: ='Financial Statements'!D36/'Financial Statements'!D$41 -> 0.012092711 | E24: ='Financial Statements'!E36/'Financial Statements'!E$41 -> 0.011594825 | F24: ='Financial Statements'!F36/'Financial Statements'!F$41 -> 0.010718007 | G24: ='Financial Statements'!G36/'Financial Statements'!G$41 -> 0.0034186791 | H24: ='Financial Statements'!H36/'Financial Statements'!H$41 -> 0.0033330497 | I24: ='Financial Statements'!I36/'Financial Statements'!I$41 -> 0.0032157861 | J24: ='Financial Statements'!J36/'Financial Statements'!J$41 -> 0.0029940501 | ... L24: ='Financial Statements'!L36/'Financial Statements'!L$41 -> 0.0029471519
B25: Reserves | C25: ='Financial Statements'!C37/'Financial Statements'!C$41 -> 0.41563734 | D25: ='Financial Statements'!D37/'Financial Statements'!D$41 -> 0.39553242 | E25: ='Financial Statements'!E37/'Financial Statements'!E$41 -> 0.41070374 | F25: ='Financial Statements'!F37/'Financial Statements'!F$41 -> 0.3976083 | G25: ='Financial Statements'!G37/'Financial Statements'!G$41 -> 0.6901222 | H25: ='Financial Statements'!H37/'Financial Statements'!H$41 -> 0.69250844 | I25: ='Financial Statements'!I37/'Financial Statements'!I$41 -> 0.68515402 | J25: ='Financial Statements'!J37/'Financial Statements'!J$41 -> 0.64955599 | ... L25: ='Financial Statements'!L37/'Financial Statements'!L$41 -> 0.60829216
B26: Borrowings | C26: ='Financial Statements'!C38/'Financial Statements'!C$41 -> 0.017636572 | D26: ='Financial Statements'!D38/'Financial Statements'!D$41 -> 0 | E26: ='Financial Statements'!E38/'Financial Statements'!E$41 -> 0.0053142949 | F26: ='Financial Statements'!F38/'Financial Statements'!F$41 -> 0 | G26: ='Financial Statements'!G38/'Financial Statements'!G$41 -> 0 | H26: ='Financial Statements'!H38/'Financial Statements'!H$41 -> 0.014793067 | I26: ='Financial Statements'!I38/'Financial Statements'!I$41 -> 0.016681035 | J26: ='Financial Statements'!J38/'Financial Statements'!J$41 -> 0.018907108 | ... L26: ='Financial Statements'!L38/'Financial Statements'!L$41 -> 0.018535704
B27: Other Liabilities | C27: ='Financial Statements'!C39/'Financial Statements'!C$41 -> 0.15911117 | D27: ='Financial Statements'!D39/'Financial Statements'!D$41 -> 0.19096406 | E27: ='Financial Statements'!E39/'Financial Statements'!E$41 -> 0.18557088 | F27: ='Financial Statements'!F39/'Financial Statements'!F$41 -> 0.21778395 | G27: ='Financial Statements'!G39/'Financial Statements'!G$41 -> 0.17841141 | H27: ='Financial Statements'!H39/'Financial Statements'!H$41 -> 0.16075228 | I27: ='Financial Statements'!I39/'Financial Statements'!I$41 -> 0.16393667 | J27: ='Financial Statements'!J39/'Financial Statements'!J$41 -> 0.19494451 | ... L27: ='Financial Statements'!L39/'Financial Statements'!L$41 -> 0.2031152
B28: Trade Payables | C28: ='Financial Statements'!C40/'Financial Statements'!C$41 -> 0.39386222 | D28: ='Financial Statements'!D40/'Financial Statements'!D$41 -> 0.40141082 | E28: ='Financial Statements'!E40/'Financial Statements'!E$41 -> 0.38681625 | F28: ='Financial Statements'!F40/'Financial Statements'!F$41 -> 0.37388974 | G28: ='Financial Statements'!G40/'Financial Statements'!G$41 -> 0.12804772 | H28: ='Financial Statements'!H40/'Financial Statements'!H$41 -> 0.12861317 | I28: ='Financial Statements'!I40/'Financial Statements'!I$41 -> 0.13101249 | J28: ='Financial Statements'!J40/'Financial Statements'!J$41 -> 0.13359834 | ... L28: ='Financial Statements'!L40/'Financial Statements'!L$41 -> 0.16710978
B29: Total Equity + Liabilities | C29: ='Financial Statements'!C41/'Financial Statements'!C41 -> 1 | D29: ='Financial Statements'!D41/'Financial Statements'!D41 -> 1 | E29: ='Financial Statements'!E41/'Financial Statements'!E41 -> 1 | F29: ='Financial Statements'!F41/'Financial Statements'!F41 -> 1 | G29: ='Financial Statements'!G41/'Financial Statements'!G41 -> 1 | H29: ='Financial Statements'!H41/'Financial Statements'!H41 -> 1 | I29: ='Financial Statements'!I41/'Financial Statements'!I41 -> 1 | J29: ='Financial Statements'!J41/'Financial Statements'!J41 -> 1 | ... L29: ='Financial Statements'!L41/'Financial Statements'!L41 -> 1
B31: Net Block | C31: ='Financial Statements'!C43/'Financial Statements'!C$53 -> 0.28135744 | D31: ='Financial Statements'!D43/'Financial Statements'!D$53 -> 0.25349905 | E31: ='Financial Statements'!E43/'Financial Statements'!E$53 -> 0.25310001 | F31: ='Financial Statements'!F43/'Financial Statements'!F$53 -> 0.27187019 | G31: ='Financial Statements'!G43/'Financial Statements'!G$53 -> 0.74837067 | H31: ='Financial Statements'!H43/'Financial Statements'!H$53 -> 0.73005134 | I31: ='Financial Statements'!I43/'Financial Statements'!I$53 -> 0.72085608 | J31: ='Financial Statements'!J43/'Financial Statements'!J$53 -> 0.68473289 | ... L31: ='Financial Statements'!L43/'Financial Statements'!L$53 -> 0.72020868
B32: Capital work in progress | C32: ='Financial Statements'!C44/'Financial Statements'!C$53 -> 0.014580415 | D32: ='Financial Statements'!D44/'Financial Statements'!D$53 -> 0.02580898 | E32: ='Financial Statements'!E44/'Financial Statements'!E$53 -> 0.021793977 | F32: ='Financial Statements'!F44/'Financial Statements'!F$53 -> 0.029623381 | G32: ='Financial Statements'!G44/'Financial Statements'!G$53 -> 0.01083794 | H32: ='Financial Statements'!H44/'Financial Statements'!H$53 -> 0.018622529 | I32: ='Financial Statements'!I44/'Financial Statements'!I$53 -> 0.01549051 | J32: ='Financial Statements'!J44/'Financial Statements'!J$53 -> 0.013059155 | ... L32: ='Financial Statements'!L44/'Financial Statements'!L$53 -> 0.011036143
